<sdf version='1.6'>
  <world name='default'>
    <light name='sun' type='directional'>
      <cast_shadows>1</cast_shadows>
      <pose frame=''>0 0 10 0 -0 0</pose>
      <diffuse>0.8 0.8 0.8 1</diffuse>
      <specular>0.1 0.1 0.1 1</specular>
      <attenuation>
        <range>1000</range>
        <constant>0.9</constant>
        <linear>0.01</linear>
        <quadratic>0.001</quadratic>
      </attenuation>
      <direction>-0.5 0.5 -1</direction>
    </light>
    <model name='ground_plane'>
      <static>1</static>
      <link name='link'>
        <collision name='collision'>
          <geometry>
            <plane>
              <normal>0 0 1</normal>
              <size>100 100</size>
            </plane>
          </geometry>
          <surface>
            <friction>
              <ode>
                <mu>100</mu>
                <mu2>50</mu2>
              </ode>
              <torsional>
                <ode/>
              </torsional>
            </friction>
            <contact>
              <ode/>
            </contact>
            <bounce/>
          </surface>
          <max_contacts>10</max_contacts>
        </collision>
        <visual name='visual'>
          <cast_shadows>0</cast_shadows>
          <geometry>
            <plane>
              <normal>0 0 1</normal>
              <size>100 100</size>
            </plane>
          </geometry>
          <material>
            <script>
              <uri>file://media/materials/scripts/gazebo.material</uri>
              <name>Gazebo/Grey</name>
            </script>
          </material>
        </visual>
        <self_collide>0</self_collide>
        <kinematic>0</kinematic>
        <gravity>1</gravity>
      </link>
    </model>
    <gravity>0 0 -9.8</gravity>
    <magnetic_field>6e-06 2.3e-05 -4.2e-05</magnetic_field>
    <atmosphere type='adiabatic'/>
    <physics name='default_physics' default='0' type='ode'>
      <max_step_size>0.001</max_step_size>
      <real_time_factor>1</real_time_factor>
      <real_time_update_rate>1000</real_time_update_rate>
    </physics>
    <scene>
      <ambient>0.4 0.4 0.4 1</ambient>
      <background>0.7 0.7 0.7 1</background>
      <shadows>1</shadows>
    </scene>
    <spherical_coordinates>
      <surface_model>EARTH_WGS84</surface_model>
      <latitude_deg>0</latitude_deg>
      <longitude_deg>0</longitude_deg>
      <elevation>0</elevation>
      <heading_deg>0</heading_deg>
    </spherical_coordinates>
    <model name='robot_blue'>
      <link name='chassis_link'>
        <pose frame=''>0 0 0 0 -0 0</pose>
        <inertial>
          <pose frame=''>-0.014 0 0.02 0 -0 0</pose>
          <mass>7.22</mass>
          <inertia>
            <ixx>0.062311</ixx>
            <ixy>-0.0013811</ixy>
            <ixz>0.012329</ixz>
            <iyy>0.19086</iyy>
            <iyz>0.00083893</iyz>
            <izz>0.21623</izz>
          </inertia>
        </inertial>
        <collision name='chassis_link_collision'>
          <pose frame=''>0 0 0 0 -0 0</pose>
          <geometry>
            <mesh>
              <scale>1 1 1</scale>
              <uri>/home/destinxxy/catkin_ws/src/gimbal_chassis_v0/meshes/chassis_link.STL</uri>
            </mesh>
          </geometry>
          <surface>
            <contact>
              <ode/>
            </contact>
            <friction>
              <ode/>
              <torsional>
                <ode/>
              </torsional>
            </friction>
            <bounce/>
          </surface>
          <max_contacts>10</max_contacts>
        </collision>
        <visual name='chassis_link_visual'>
          <pose frame=''>0 0 0 0 -0 0</pose>
          <geometry>
            <mesh>
              <scale>1 1 1</scale>
              <uri>/home/destinxxy/catkin_ws/src/gimbal_chassis_v0/meshes/chassis_link.STL</uri>
            </mesh>
          </geometry>
          <material>
            <script>
              <name>Gazebo/Blue</name>
              <uri>file://media/materials/scripts/gazebo.material</uri>
            </script>
          </material>
        </visual>
        <velocity_decay/>
        <gravity>1</gravity>
        <velocity_decay/>
        <self_collide>0</self_collide>
        <pose frame=''>0 0 0.25 3.14159 0.001593 3.14159</pose>
        <kinematic>0</kinematic>
      </link>
      <link name='LB_Link'>
        <pose frame=''>-0.20747 -0.21083 0.065436 1.5708 -0 0</pose>
        <inertial>
          <pose frame=''>0 0 0.014 0 -0 0</pose>
          <mass>0.83</mass>
          <inertia>
            <ixx>0.0016713</ixx>
            <ixy>0</ixy>
            <ixz>0</ixz>
            <iyy>0.0016723</iyy>
            <iyz>-3.7351e-05</iyz>
            <izz>0.0028024</izz>
          </inertia>
        </inertial>
        <collision name='LB_Link_collision'>
          <pose frame=''>0 0 0 0 -0 0</pose>
          <geometry>
            <cylinder>
              <length>0.05</length>
              <radius>0.075</radius>
            </cylinder>
          </geometry>
          <surface>
            <contact>
              <ode/>
            </contact>
            <friction>
              <ode>
                <mu>100</mu>
                <mu2>100</mu2>
              </ode>
              <torsional>
                <ode/>
              </torsional>
            </friction>
            <bounce/>
          </surface>
          <max_contacts>10</max_contacts>
        </collision>
        <visual name='LB_Link_visual'>
          <pose frame=''>0 0 0 0 -0 0</pose>
          <geometry>
            <mesh>
              <scale>1 1 1</scale>
              <uri>/home/destinxxy/catkin_ws/src/gimbal_chassis_v0/meshes/LB_Link.STL</uri>
            </mesh>
          </geometry>
          <material>
            <script>
              <name>Gazebo/Grey</name>
              <uri>file://media/materials/scripts/gazebo.material</uri>
            </script>
          </material>
        </visual>
        <gravity>1</gravity>
        <velocity_decay/>
        <self_collide>0</self_collide>
        <kinematic>0</kinematic>
      </link>
      <joint name='LB_joint' type='revolute'>
        <child>LB_Link</child>
        <parent>chassis_link</parent>
        <axis>
          <xyz>0 -1 -4e-06</xyz>
          <limit>
            <lower>-1e+16</lower>
            <upper>1e+16</upper>
          </limit>
          <dynamics>
            <damping>0</damping>
            <friction>0</friction>
            <spring_reference>0</spring_reference>
            <spring_stiffness>0</spring_stiffness>
          </dynamics>
          <use_parent_model_frame>1</use_parent_model_frame>
        </axis>
      </joint>
      <link name='LF_Link'>
        <pose frame=''>0.22436 -0.21083 0.065436 1.5708 -0 0</pose>
        <inertial>
          <pose frame=''>0 0 -0.014 0 -0 0</pose>
          <mass>0.83</mass>
          <inertia>
            <ixx>0.0016709</ixx>
            <ixy>0</ixy>
            <ixz>0</ixz>
            <iyy>0.0016717</iyy>
            <iyz>3.2768e-05</iyz>
            <izz>0.0028024</izz>
          </inertia>
        </inertial>
        <collision name='LF_Link_collision'>
          <pose frame=''>0 0 0 0 -0 0</pose>
          <geometry>
            <cylinder>
              <length>0.05</length>
              <radius>0.075</radius>
            </cylinder>
          </geometry>
          <surface>
            <contact>
              <ode/>
            </contact>
            <friction>
              <ode>
                <mu>100</mu>
                <mu2>100</mu2>
              </ode>
              <torsional>
                <ode/>
              </torsional>
            </friction>
            <bounce/>
          </surface>
          <max_contacts>10</max_contacts>
        </collision>
        <visual name='LF_Link_visual'>
          <pose frame=''>0 0 0 0 -0 0</pose>
          <geometry>
            <mesh>
              <scale>1 1 1</scale>
              <uri>/home/destinxxy/catkin_ws/src/gimbal_chassis_v0/meshes/LF_Link.STL</uri>
            </mesh>
          </geometry>
          <material>
            <script>
              <name>Gazebo/Grey</name>
              <uri>file://media/materials/scripts/gazebo.material</uri>
            </script>
          </material>
        </visual>
        <gravity>1</gravity>
        <velocity_decay/>
        <self_collide>0</self_collide>
        <kinematic>0</kinematic>
      </link>
      <joint name='LF_joint' type='revolute'>
        <child>LF_Link</child>
        <parent>chassis_link</parent>
        <axis>
          <xyz>0 -1 -4e-06</xyz>
          <limit>
            <lower>-1e+16</lower>
            <upper>1e+16</upper>
          </limit>
          <dynamics>
            <damping>0</damping>
            <friction>0</friction>
            <spring_reference>0</spring_reference>
            <spring_stiffness>0</spring_stiffness>
          </dynamics>
          <use_parent_model_frame>1</use_parent_model_frame>
        </axis>
      </joint>
      <link name='RB_Link'>
        <pose frame=''>-0.20764 0.21473 0.065436 1.5708 -0 0</pose>
        <inertial>
          <pose frame=''>0 0 -0.014 0 -0 0</pose>
          <mass>0.83</mass>
          <inertia>
            <ixx>0.0016709</ixx>
            <ixy>0</ixy>
            <ixz>0</ixz>
            <iyy>0.0016717</iyy>
            <iyz>3.2768e-05</iyz>
            <izz>0.0028024</izz>
          </inertia>
        </inertial>
        <collision name='RB_Link_collision'>
          <pose frame=''>0 0 0 0 -0 0</pose>
          <geometry>
            <cylinder>
              <length>0.05</length>
              <radius>0.075</radius>
            </cylinder>
          </geometry>
          <surface>
            <contact>
              <ode/>
            </contact>
            <friction>
              <ode>
                <mu>100</mu>
                <mu2>100</mu2>
              </ode>
              <torsional>
                <ode/>
              </torsional>
            </friction>
            <bounce/>
          </surface>
          <max_contacts>10</max_contacts>
        </collision>
        <visual name='RB_Link_visual'>
          <pose frame=''>0 0 0 0 -0 0</pose>
          <geometry>
            <mesh>
              <scale>1 1 1</scale>
              <uri>/home/destinxxy/catkin_ws/src/gimbal_chassis_v0/meshes/RB_Link.STL</uri>
            </mesh>
          </geometry>
          <material>
            <script>
              <name>Gazebo/Grey</name>
              <uri>file://media/materials/scripts/gazebo.material</uri>
            </script>
          </material>
        </visual>
        <gravity>1</gravity>
        <velocity_decay/>
        <self_collide>0</self_collide>
        <kinematic>0</kinematic>
      </link>
      <joint name='RB_joint' type='revolute'>
        <child>RB_Link</child>
        <parent>chassis_link</parent>
        <axis>
          <xyz>0 -1 -4e-06</xyz>
          <limit>
            <lower>-1e+16</lower>
            <upper>1e+16</upper>
          </limit>
          <dynamics>
            <damping>0</damping>
            <friction>0</friction>
            <spring_reference>0</spring_reference>
            <spring_stiffness>0</spring_stiffness>
          </dynamics>
          <use_parent_model_frame>1</use_parent_model_frame>
        </axis>
      </joint>
      <link name='RF_Link'>
        <pose frame=''>0.22419 0.21473 0.065436 1.5708 -0 0</pose>
        <inertial>
          <pose frame=''>0 0 0.014 0 -0 0</pose>
          <mass>0.83</mass>
          <inertia>
            <ixx>0.0016713</ixx>
            <ixy>0</ixy>
            <ixz>0</ixz>
            <iyy>0.00167234</iyy>
            <iyz>-3.2624e-05</iyz>
            <izz>0.0028024</izz>
          </inertia>
        </inertial>
        <collision name='RF_Link_collision'>
          <pose frame=''>0 0 0 0 -0 0</pose>
          <geometry>
            <cylinder>
              <length>0.05</length>
              <radius>0.075</radius>
            </cylinder>
          </geometry>
          <surface>
            <contact>
              <ode/>
            </contact>
            <friction>
              <ode>
                <mu>100</mu>
                <mu2>100</mu2>
              </ode>
              <torsional>
                <ode/>
              </torsional>
            </friction>
            <bounce/>
          </surface>
          <max_contacts>10</max_contacts>
        </collision>
        <visual name='RF_Link_visual'>
          <pose frame=''>0 0 0 0 -0 0</pose>
          <geometry>
            <mesh>
              <scale>1 1 1</scale>
              <uri>/home/destinxxy/catkin_ws/src/gimbal_chassis_v0/meshes/RF_Link.STL</uri>
            </mesh>
          </geometry>
          <material>
            <script>
              <name>Gazebo/Grey</name>
              <uri>file://media/materials/scripts/gazebo.material</uri>
            </script>
          </material>
        </visual>
        <gravity>1</gravity>
        <velocity_decay/>
        <self_collide>0</self_collide>
        <kinematic>0</kinematic>
      </link>
      <joint name='RF_joint' type='revolute'>
        <child>RF_Link</child>
        <parent>chassis_link</parent>
        <axis>
          <xyz>0 -1 -4e-06</xyz>
          <limit>
            <lower>-1e+16</lower>
            <upper>1e+16</upper>
          </limit>
          <dynamics>
            <damping>0</damping>
            <friction>0</friction>
            <spring_reference>0</spring_reference>
            <spring_stiffness>0</spring_stiffness>
          </dynamics>
          <use_parent_model_frame>1</use_parent_model_frame>
        </axis>
      </joint>
      <link name='gimbal_down_Link'>
        <pose frame=''>0.12062 -0.009265 -0.07153 0 -0 0</pose>
        <inertial>
          <pose frame=''>-0.014 0 0.02 0 -0 0</pose>
          <mass>7.22</mass>
          <inertia>
            <ixx>0.062311</ixx>
            <ixy>-0.0013811</ixy>
            <ixz>0.012329</ixz>
            <iyy>0.19086</iyy>
            <iyz>0.00083893</iyz>
            <izz>0.21623</izz>
          </inertia>
        </inertial>
        <collision name='gimbal_down_Link_collision'>
          <pose frame=''>0 0 0 0 -0 0</pose>
          <geometry>
            <mesh>
              <scale>1 1 1</scale>
              <uri>/home/destinxxy/catkin_ws/src/gimbal_chassis_v0/meshes/gimbal_down_Link.STL</uri>
            </mesh>
          </geometry>
          <max_contacts>10</max_contacts>
          <surface>
            <contact>
              <ode/>
            </contact>
            <bounce/>
            <friction>
              <torsional>
                <ode/>
              </torsional>
              <ode/>
            </friction>
          </surface>
        </collision>
        <visual name='gimbal_down_Link_visual'>
          <pose frame=''>0 0 0 0 -0 0</pose>
          <geometry>
            <mesh>
              <scale>1 1 1</scale>
              <uri>/home/destinxxy/catkin_ws/src/gimbal_chassis_v0/meshes/gimbal_down_Link.STL</uri>
            </mesh>
          </geometry>
        </visual>
        <self_collide>0</self_collide>
        <kinematic>0</kinematic>
        <gravity>1</gravity>
      </link>
      <joint name='yaw_joint' type='revolute'>
        <child>gimbal_down_Link</child>
        <parent>chassis_link</parent>
        <axis>
          <xyz>0 0 1</xyz>
          <limit>
            <lower>-1e+16</lower>
            <upper>1e+16</upper>
          </limit>
          <dynamics>
            <spring_reference>0</spring_reference>
            <spring_stiffness>0</spring_stiffness>
          </dynamics>
          <use_parent_model_frame>1</use_parent_model_frame>
        </axis>
      </joint>
      <link name='gimbal_up_Link'>
        <pose frame=''>0.12062 0.015736 -0.17403 0 -0 0</pose>
        <inertial>
          <pose frame=''>-0.015 -0.036 -0.015 0 -0 0</pose>
          <mass>0.28569</mass>
          <inertia>
            <ixx>0.00097613</ixx>
            <ixy>0.00012133</ixy>
            <ixz>0.00025298</ixz>
            <iyy>0.00015619</iyy>
            <iyz>0.00018335</iyz>
            <izz>0.0018564</izz>
          </inertia>
        </inertial>
        <collision name='gimbal_up_Link_collision'>
          <pose frame=''>0 -0.02 0 0 -0 0</pose>
          <geometry>
            <mesh>
              <scale>1 1 1</scale>
              <uri>/home/destinxxy/catkin_ws/src/gimbal_chassis_v0/meshes/gimbal_up_Link.STL</uri>
            </mesh>
          </geometry>
          <max_contacts>10</max_contacts>
          <surface>
            <contact>
              <ode/>
            </contact>
            <bounce/>
            <friction>
              <torsional>
                <ode/>
              </torsional>
              <ode/>
            </friction>
          </surface>
        </collision>
        <visual name='gimbal_up_Link_visual'>
          <pose frame=''>0 0 0 0 -0 0</pose>
          <geometry>
            <mesh>
              <scale>1 1 1</scale>
              <uri>/home/destinxxy/catkin_ws/src/gimbal_chassis_v0/meshes/gimbal_up_Link.STL</uri>
            </mesh>
          </geometry>
        </visual>
        <gravity>1</gravity>
        <velocity_decay/>
        <self_collide>0</self_collide>
        <sensor name='camera1' type='camera'>
          <update_rate>30</update_rate>
          <camera name='head'>
            <horizontal_fov>1.39626</horizontal_fov>
            <image>
              <width>800</width>
              <height>800</height>
              <format>R8G8B8</format>
            </image>
            <clip>
              <near>0.02</near>
              <far>300</far>
            </clip>
            <noise>
              <type>gaussian</type>
              <mean>0</mean>
              <stddev>0.007</stddev>
            </noise>
          </camera>
          <plugin name='camera_controller' filename='libgazebo_ros_camera.so'>
            <alwaysOn>true</alwaysOn>
            <updateRate>0.0</updateRate>
            <cameraName>blue/camera1</cameraName>
            <imageTopicName>image_raw</imageTopicName>
            <cameraInfoTopicName>camera_info</cameraInfoTopicName>
            <frameName>camera_Link</frameName>
            <hackBaseline>0.07</hackBaseline>
            <distortionK1>0.0</distortionK1>
            <distortionK2>0.0</distortionK2>
            <distortionK3>0.0</distortionK3>
            <distortionT1>0.0</distortionT1>
            <distortionT2>0.0</distortionT2>
            <robotNamespace>/</robotNamespace>
          </plugin>
          <pose frame=''>0.1 -0.03336 -0.019 3.14 -0 0</pose>
        </sensor>
        <kinematic>0</kinematic>
      </link>
      <joint name='pitch_joint' type='revolute'>
        <child>gimbal_up_Link</child>
        <parent>gimbal_down_Link</parent>
        <axis>
          <xyz>0 1 0</xyz>
          <limit>
            <lower>-1e+16</lower>
            <upper>1e+16</upper>
          </limit>
          <dynamics>
            <spring_reference>0</spring_reference>
            <spring_stiffness>0</spring_stiffness>
          </dynamics>
          <use_parent_model_frame>1</use_parent_model_frame>
        </axis>
      </joint>
      <static>0</static>
      <plugin name='rm_drive_controller' filename='libRMDrive.so'>
        <updateRate>50</updateRate>
        <robotNamespace>/</robotNamespace>
        <leftFrontJoint>LF_joint</leftFrontJoint>
        <rightFrontJoint>RF_joint</rightFrontJoint>
        <leftRearJoint>LB_joint</leftRearJoint>
        <rightRearJoint>RB_joint</rightRearJoint>
        <wheelSeparation>0.4</wheelSeparation>
        <wheelDiameter>0.155</wheelDiameter>
        <gimbalYawJoint>yaw_joint</gimbalYawJoint>
        <gimbalPitchJoint>pitch_joint</gimbalPitchJoint>
        <robotBaseFrame>chassis_link</robotBaseFrame>
        <torque>4.5</torque>
        <commandTopic>cmd_vel_0</commandTopic>
        <broadcastTF>0</broadcastTF>
      </plugin>
      <pose frame=''>0 0 0.25 3.14159 0.001593 3.14159</pose>
    </model>
    <model name='rm_field_0'>
      <link name='base_link'>
        <pose frame=''>0 0 0 0 -0 0</pose>
        <inertial>
          <pose frame=''>13.9618 7.48557 0.322061 0 -0 0</pose>
          <mass>65716.2</mass>
          <inertia>
            <ixx>993263</ixx>
            <ixy>0</ixy>
            <ixz>47.7007</ixz>
            <iyy>5.27232e+06</iyy>
            <iyz>53.5134</iyz>
            <izz>6.26306e+06</izz>
          </inertia>
        </inertial>
        <self_collide>0</self_collide>
        <kinematic>0</kinematic>
        <gravity>1</gravity>
        <visual name='base_link_visual'>
          <pose frame=''>0 0 0 0 -0 0</pose>
          <geometry>
            <mesh>
              <uri>/home/destinxxy/catkin_ws/src/rm_field/meshes/base_link_g.STL</uri>
              <scale>1 1 1</scale>
            </mesh>
          </geometry>
          <cast_shadows>1</cast_shadows>
          <transparency>0</transparency>
          <material>
            <shader type='vertex'>
              <normal_map>__default__</normal_map>
            </shader>
            <ambient>0.3 0.3 0.3 1</ambient>
            <diffuse>0.7 0.7 0.7 1</diffuse>
            <specular>0.01 0.01 0.01 1</specular>
            <emissive>0 0 0 1</emissive>
            <script>
              <name>Gazebo/Grey</name>
              <uri>__default__</uri>
            </script>
          </material>
        </visual>
        <visual name='base_link_fixed_joint_lump__blue_visual_1'>
          <pose frame=''>0 0 0 0 -0 0</pose>
          <geometry>
            <mesh>
              <scale>1 1 1</scale>
              <uri>/home/destinxxy/catkin_ws/src/rm_field/meshes/blue.STL</uri>
            </mesh>
          </geometry>
          <cast_shadows>1</cast_shadows>
          <transparency>0</transparency>
          <material>
            <shader type='vertex'>
              <normal_map>__default__</normal_map>
            </shader>
            <ambient>0.3 0.3 0.7 1</ambient>
            <diffuse>0.7 0.7 0.7 1</diffuse>
            <specular>0.01 0.01 0.01 1</specular>
            <emissive>0 0 0 1</emissive>
            <script>
              <name>ModelPreview_3::base_link::base_link_fixed_joint_lump__blue_visual_1_MATERIAL_</name>
              <uri>__default__</uri>
            </script>
          </material>
        </visual>
        <visual name='base_link_fixed_joint_lump__red_visual_2'>
          <pose frame=''>0 0 0 0 -0 0</pose>
          <geometry>
            <mesh>
              <scale>1 1 1</scale>
              <uri>/home/destinxxy/catkin_ws/src/rm_field/meshes/red.STL</uri>
            </mesh>
          </geometry>
          <cast_shadows>1</cast_shadows>
          <transparency>0</transparency>
          <material>
            <shader type='vertex'>
              <normal_map>__default__</normal_map>
            </shader>
            <ambient>0.7 0.3 0.3 1</ambient>
            <diffuse>0.7 0.7 0.7 1</diffuse>
            <specular>0.01 0.01 0.01 1</specular>
            <emissive>0 0 0 1</emissive>
            <script>
              <name>ModelPreview_3::base_link::base_link_fixed_joint_lump__red_visual_2_MATERIAL_</name>
              <uri>__default__</uri>
            </script>
          </material>
        </visual>
        <collision name='base_link_collision'>
          <laser_retro>0</laser_retro>
          <max_contacts>10</max_contacts>
          <pose frame=''>0 0 0 0 -0 0</pose>
          <geometry>
            <mesh>
              <uri>/home/destinxxy/catkin_ws/src/rm_field/meshes/base_link_g.STL</uri>
              <scale>1 1 1</scale>
            </mesh>
          </geometry>
          <surface>
            <friction>
              <ode>
                <mu>100</mu>
                <mu2>100</mu2>
                <fdir1>0 0 0</fdir1>
                <slip1>0</slip1>
                <slip2>0</slip2>
              </ode>
              <torsional>
                <coefficient>1</coefficient>
                <patch_radius>0</patch_radius>
                <surface_radius>0</surface_radius>
                <use_patch_radius>1</use_patch_radius>
                <ode>
                  <slip>0</slip>
                </ode>
              </torsional>
            </friction>
            <bounce>
              <restitution_coefficient>0</restitution_coefficient>
              <threshold>1e+06</threshold>
            </bounce>
            <contact>
              <collide_without_contact>0</collide_without_contact>
              <collide_without_contact_bitmask>1</collide_without_contact_bitmask>
              <collide_bitmask>1</collide_bitmask>
              <ode>
                <soft_cfm>0</soft_cfm>
                <soft_erp>0.2</soft_erp>
                <kp>1e+13</kp>
                <kd>1</kd>
                <max_vel>0.01</max_vel>
                <min_depth>0</min_depth>
              </ode>
              <bullet>
                <split_impulse>1</split_impulse>
                <split_impulse_penetration_threshold>-0.01</split_impulse_penetration_threshold>
                <soft_cfm>0</soft_cfm>
                <soft_erp>0.2</soft_erp>
                <kp>1e+13</kp>
                <kd>1</kd>
              </bullet>
            </contact>
          </surface>
        </collision>
        <collision name='base_link_fixed_joint_lump__blue_collision_1'>
          <laser_retro>0</laser_retro>
          <max_contacts>10</max_contacts>
          <pose frame=''>0 0 0 0 -0 0</pose>
          <geometry>
            <mesh>
              <uri>/home/destinxxy/catkin_ws/src/rm_field/meshes/blue.STL</uri>
              <scale>1 1 1</scale>
            </mesh>
          </geometry>
          <surface>
            <friction>
              <ode>
                <mu>100</mu>
                <mu2>100</mu2>
                <fdir1>0 0 0</fdir1>
                <slip1>0</slip1>
                <slip2>0</slip2>
              </ode>
              <torsional>
                <coefficient>1</coefficient>
                <patch_radius>0</patch_radius>
                <surface_radius>0</surface_radius>
                <use_patch_radius>1</use_patch_radius>
                <ode>
                  <slip>0</slip>
                </ode>
              </torsional>
            </friction>
            <bounce>
              <restitution_coefficient>0</restitution_coefficient>
              <threshold>1e+06</threshold>
            </bounce>
            <contact>
              <collide_without_contact>0</collide_without_contact>
              <collide_without_contact_bitmask>1</collide_without_contact_bitmask>
              <collide_bitmask>1</collide_bitmask>
              <ode>
                <soft_cfm>0</soft_cfm>
                <soft_erp>0.2</soft_erp>
                <kp>1e+13</kp>
                <kd>1</kd>
                <max_vel>0.01</max_vel>
                <min_depth>0</min_depth>
              </ode>
              <bullet>
                <split_impulse>1</split_impulse>
                <split_impulse_penetration_threshold>-0.01</split_impulse_penetration_threshold>
                <soft_cfm>0</soft_cfm>
                <soft_erp>0.2</soft_erp>
                <kp>1e+13</kp>
                <kd>1</kd>
              </bullet>
            </contact>
          </surface>
        </collision>
        <collision name='base_link_fixed_joint_lump__red_collision_2'>
          <laser_retro>0</laser_retro>
          <max_contacts>10</max_contacts>
          <pose frame=''>0 0 0 0 -0 0</pose>
          <geometry>
            <mesh>
              <uri>/home/destinxxy/catkin_ws/src/rm_field/meshes/red.STL</uri>
              <scale>1 1 1</scale>
            </mesh>
          </geometry>
          <surface>
            <friction>
              <ode>
                <mu>100</mu>
                <mu2>100</mu2>
                <fdir1>0 0 0</fdir1>
                <slip1>0</slip1>
                <slip2>0</slip2>
              </ode>
              <torsional>
                <coefficient>1</coefficient>
                <patch_radius>0</patch_radius>
                <surface_radius>0</surface_radius>
                <use_patch_radius>1</use_patch_radius>
                <ode>
                  <slip>0</slip>
                </ode>
              </torsional>
            </friction>
            <bounce>
              <restitution_coefficient>0</restitution_coefficient>
              <threshold>1e+06</threshold>
            </bounce>
            <contact>
              <collide_without_contact>0</collide_without_contact>
              <collide_without_contact_bitmask>1</collide_without_contact_bitmask>
              <collide_bitmask>1</collide_bitmask>
              <ode>
                <soft_cfm>0</soft_cfm>
                <soft_erp>0.2</soft_erp>
                <kp>1e+13</kp>
                <kd>1</kd>
                <max_vel>0.01</max_vel>
                <min_depth>0</min_depth>
              </ode>
              <bullet>
                <split_impulse>1</split_impulse>
                <split_impulse_penetration_threshold>-0.01</split_impulse_penetration_threshold>
                <soft_cfm>0</soft_cfm>
                <soft_erp>0.2</soft_erp>
                <kp>1e+13</kp>
                <kd>1</kd>
              </bullet>
            </contact>
          </surface>
        </collision>
      </link>
      <static>0</static>
      <allow_auto_disable>1</allow_auto_disable>
      <pose frame=''>0.000181 -0.000193 0 0 -0 0</pose>
    </model>
    <state world_name='default'>
      <sim_time>0 0</sim_time>
      <real_time>0 0</real_time>
      <wall_time>1523716524 875654619</wall_time>
      <iterations>0</iterations>
      <model name='ground_plane'>
        <pose frame=''>0 0 0 0 -0 0</pose>
        <scale>1 1 1</scale>
        <link name='link'>
          <pose frame=''>0 0 0 0 -0 0</pose>
          <velocity>0 0 0 0 -0 0</velocity>
          <acceleration>0 0 0 0 -0 0</acceleration>
          <wrench>0 0 0 0 -0 0</wrench>
        </link>
      </model>
      <model name='rm_field_0'>
        <pose frame=''>0 0 0.01 0 -0 0</pose>
        <scale>1 1 1</scale>
        <link name='base_link'>
          <pose frame=''>0 0 0.01 0 -0 0</pose>
          <velocity>0 0 0 0 -0 0</velocity>
          <acceleration>0 0 0 0 -0 0</acceleration>
          <wrench>0 0 0 0 -0 0</wrench>
        </link>
      </model>
      <model name='robot_blue'>
        <pose frame=''>2 2 0.6 3.14159 0.001593 -0.001593</pose>
        <scale>1 1 1</scale>
        <link name='LB_Link'>
          <pose frame=''>1.79276 2.21116 0.534895 -1.57079 0.001593 -0.001593</pose>
          <velocity>0 0 0 0 -0 0</velocity>
          <acceleration>0 0 0 0 -0 0</acceleration>
          <wrench>0 0 0 0 -0 0</wrench>
        </link>
        <link name='LF_Link'>
          <pose frame=''>2.22459 2.21047 0.534207 -1.57079 0.001593 -0.001593</pose>
          <velocity>0 0 0 0 -0 0</velocity>
          <acceleration>0 0 0 0 -0 0</acceleration>
          <wrench>0 0 0 0 -0 0</wrench>
        </link>
        <link name='RB_Link'>
          <pose frame=''>1.79191 1.7856 0.534895 -1.57079 0.001593 -0.001593</pose>
          <velocity>0 0 0 0 -0 0</velocity>
          <acceleration>0 0 0 0 -0 0</acceleration>
          <wrench>0 0 0 0 -0 0</wrench>
        </link>
        <link name='RF_Link'>
          <pose frame=''>2.22374 1.78491 0.534207 -1.57079 0.001593 -0.001593</pose>
          <velocity>0 0 0 0 -0 0</velocity>
          <acceleration>0 0 0 0 -0 0</acceleration>
          <wrench>0 0 0 0 -0 0</wrench>
        </link>
        <link name='chassis_link'>
          <pose frame=''>2 2 0.6 3.14159 0.001593 -0.001593</pose>
          <velocity>0 0 0 0 -0 0</velocity>
          <acceleration>0 0 0 0 -0 0</acceleration>
          <wrench>0 0 0 0 -0 0</wrench>
        </link>
        <link name='gimbal_down_Link'>
          <pose frame=''>2.12075 2.00907 0.671338 3.14159 0.001593 -0.001593</pose>
          <velocity>0 0 0 0 -0 0</velocity>
          <acceleration>0 0 0 0 -0 0</acceleration>
          <wrench>0 0 0 0 -0 0</wrench>
        </link>
        <link name='gimbal_up_Link'>
          <pose frame=''>2.12087 1.98407 0.773838 3.14159 0.001593 -0.001593</pose>
          <velocity>0 0 0 0 -0 0</velocity>
          <acceleration>0 0 0 0 -0 0</acceleration>
          <wrench>0 0 0 0 -0 0</wrench>
        </link>
      </model>
      <light name='sun'>
        <pose frame=''>0 0 10 0 -0 0</pose>
      </light>
    </state>
    <gui fullscreen='0'>
      <camera name='user_camera'>
        <pose frame=''>13.6619 11.35 28.8293 -0 1.4858 -1.57896</pose>
        <view_controller>orbit</view_controller>
        <projection_type>perspective</projection_type>
      </camera>
    </gui>
  </world>
</sdf>
